<?xml version="1.0" ?>
<robot name="upper_leg" xmlns:xacro="http://www.ros.org/wiki/xacro">
  <xacro:include filename="$(find simple_quad_description)/urdf/leg/upper_leg.gazebo.xacro" />
  <xacro:include filename="$(find simple_quad_description)/urdf/leg/upper_leg.ros2_control.xacro" />

  <xacro:macro name="upper_leg" params="name mass *origin use_ignition">
    <material name="${name}_upper_leg_color">
      <color rgba="1.0 1.0 1.0 1.0"/>
    </material>

    <link name="${name}_upper_leg">
      <inertial>
        <origin xyz="0 0 0" rpy="0 0 0"/>
        <mass value="${mass}" />
        <inertia ixx="0.04508" ixy="0" ixz="0"
                 iyx="0" iyy="0.04592" iyz="0"
                 izx="0" izy="0" izz="0.003255"/>
      </inertial>
      <visual>
        <origin xyz="0 0 0" rpy="0 0 0"/>
        <geometry>
          <mesh filename="file://$(find simple_quad_description)/meshes/upper_leg.stl" scale="0.001 0.001 0.001"/>
        </geometry>
        <material name="${name}_upper_leg_color"/>
      </visual>
      <collision>
        <origin xyz="0 0 0" rpy="0 0 0"/>
        <geometry>
          <mesh filename="file://$(find simple_quad_description)/meshes/upper_leg.stl" scale="0.001 0.001 0.001"/>
        </geometry>
      </collision>
    </link>

    <joint name="${name}_hip_to_upper_leg_joint" type="revolute">
      <limit effort="25" lower="${-pi/2}" upper="${pi/2}" velocity="1.5"/>
      <xacro:insert_block name="origin"/>
      <parent link="${name}_hip"/>
      <child link="${name}_upper_leg"/>
      <axis xyz="0.0 1.0 0.0"/>
    </joint>

    <!-- Gazebo Plugin -->
    <xacro:upper_leg_gazebo name="${name}"/>

    <!-- ros2_control Plugin -->
    <xacro:upper_leg_ros2_control name="${name}" use_ignition="${use_ignition}"/>
  </xacro:macro>
</robot>
